<?xml version="1.0" ?>
<!-- =================================================================================== -->
<!-- |    This document was autogenerated by xacro from spot.urdf.xacro                | -->
<!-- |    EDITING THIS FILE BY HAND IS NOT RECOMMENDED                                 | -->
<!-- =================================================================================== -->
<robot name="bosdyn_spot">
  <link name="base_link">
    <visual>
      <geometry>
        <mesh filename="/home/atas/colcon_ws/install/champ_description/share/champ_description/meshes/body.dae"/>
      </geometry>
    </visual>
    <collision>
      <geometry>
        <mesh filename="/home/atas/colcon_ws/install/champ_description/share/champ_description/meshes/body_collision.stl"/>
      </geometry>
    </collision>
    <inertial>
      <mass value="16.0"/>
      <inertia ixx="0.09733333333333333" ixy="0.0" ixz="0.0" iyy="1.0246666666666666" iyz="0.0" izz="1.0449333333333333"/>
    </inertial>
  </link>
  <link name="battery">
    <visual>
      <geometry>
        <box size="0.324 0.168 0.093"/>
      </geometry>
      <material name="spot_color">
        <color rgba="0.9176470588235294 0.6549019607843137 0 1.0"/>
      </material>
    </visual>
    <collision>
      <geometry>
        <box size="0.324 0.168 0.093"/>
      </geometry>
    </collision>
    <inertial>
      <mass value="4.0"/>
      <origin rpy="0 0 0" xyz="0 0 0"/>
      <inertia ixx="0.012291" ixy="0.0" ixz="0.0" iyy="0.037875" iyz="0.0" izz="0.0444"/>
    </inertial>
  </link>
  <joint name="battery_joint" type="fixed">
    <parent link="base_link"/>
    <child link="battery"/>
    <origin rpy="0 0 0" xyz="0 0 -0.03"/>
  </joint>
  <!-- workaround for https://github.com/osrf/sdformat/issues/378 -->
  <gazebo reference="battery_joint">
    <preserveFixedJoint>true</preserveFixedJoint>
  </gazebo>
  <link name="body">
    <inertial>
      <origin rpy="0 0 0" xyz="0 0 0"/>
      <mass value="1e-5"/>
      <inertia ixx="1e-3" ixy="1e-6" ixz="1e-6" iyy="1e-3" iyz="1e-6" izz="1e-3"/>
    </inertial>
    <selfCollide>false</selfCollide>
  </link>
  <joint name="base_link_joint" type="fixed">
    <parent link="base_link"/>
    <child link="body"/>
    <origin rpy="0 0 0" xyz="0 0 0"/>
  </joint>
  <!-- workaround for https://github.com/osrf/sdformat/issues/378 -->
  <gazebo reference="base_link_joint">
    <preserveFixedJoint>true</preserveFixedJoint>
  </gazebo>
  <link name="front_rail">
    <inertial>
      <origin rpy="0 0 0" xyz="0 0 0"/>
      <mass value="1e-5"/>
      <inertia ixx="1e-3" ixy="1e-6" ixz="1e-6" iyy="1e-3" iyz="1e-6" izz="1e-3"/>
    </inertial>
    <selfCollide>false</selfCollide>
  </link>
  <joint name="front_rail_joint" type="fixed">
    <parent link="body"/>
    <child link="front_rail"/>
    <origin rpy="0 0 0" xyz="0.223 0 0.0805"/>
  </joint>
  <!-- workaround for https://github.com/osrf/sdformat/issues/378 -->
  <gazebo reference="front_rail_joint">
    <preserveFixedJoint>true</preserveFixedJoint>
  </gazebo>
  <link name="rear_rail">
    <inertial>
      <origin rpy="0 0 0" xyz="0 0 0"/>
      <mass value="1e-5"/>
      <inertia ixx="1e-3" ixy="1e-6" ixz="1e-6" iyy="1e-3" iyz="1e-6" izz="1e-3"/>
    </inertial>
    <selfCollide>false</selfCollide>
  </link>
  <joint name="rear_rail_joint" type="fixed">
    <parent link="body"/>
    <child link="rear_rail"/>
    <origin rpy="0 0 0" xyz="-0.223 0 0.0805"/>
  </joint>
  <!-- workaround for https://github.com/osrf/sdformat/issues/378 -->
  <gazebo reference="rear_rail_joint">
    <preserveFixedJoint>true</preserveFixedJoint>
  </gazebo>
  <link name="front_left_hip">
    <visual>
      <geometry>
        <mesh filename="file:///home/atas/colcon_ws/install/champ_description/share/champ_description/meshes/front_left_hip.dae"/>
      </geometry>
    </visual>
    <collision>
      <geometry>
        <mesh filename="file:///home/atas/colcon_ws/install/champ_description/share/champ_description/meshes/front_left_hip_collision.stl"/>
      </geometry>
    </collision>
    <inertial>
      <mass value="2.0"/>
      <inertia ixx="0.0026999999999999997" ixy="0.0" ixz="0.0" iyy="0.004166666666666667" iyz="0.0" izz="0.004166666666666667"/>
    </inertial>
  </link>
  <joint name="front_left_hip_x" type="revolute">
    <origin rpy="0 0 0" xyz="0.29785 0.055 0"/>
    <axis xyz="1 0 0"/>
    <parent link="base_link"/>
    <child link="front_left_hip"/>
    <limit effort="160" lower="-0.78539816339744827899" upper="0.78539816339744827899" velocity="30"/>
    <dynamics damping="0.0" friction="0.0"/>
  </joint>
  <link name="front_left_upper_leg">
    <visual>
      <geometry>
        <mesh filename="file:///home/atas/colcon_ws/install/champ_description/share/champ_description/meshes/front_left_upper_leg.dae"/>
      </geometry>
    </visual>
    <collision>
      <geometry>
        <mesh filename="file:///home/atas/colcon_ws/install/champ_description/share/champ_description/meshes/front_left_upper_leg_collision.stl"/>
      </geometry>
    </collision>
    <inertial>
      <origin rpy="0 0 0" xyz="0 0 -0.14"/>
      <mass value="1.0"/>
      <inertia ixx="0.015533416666666664" ixy="0.0" ixz="0.0" iyy="0.015533416666666664" iyz="0.0" izz="0.0009626666666666666"/>
    </inertial>
  </link>
  <joint name="front_left_hip_y" type="revolute">
    <origin rpy="0 0 0" xyz="0 0.110945 0"/>
    <axis xyz="0 1 0"/>
    <parent link="front_left_hip"/>
    <child link="front_left_upper_leg"/>
    <limit effort="160" lower="-0.89884456477707963539" upper="2.2951079663725435509" velocity="30"/>
    <dynamics damping="0.0" friction="0.0"/>
  </joint>
  <link name="front_left_lower_leg">
    <visual>
      <geometry>
        <mesh filename="file:///home/atas/colcon_ws/install/champ_description/share/champ_description/meshes/front_left_lower_leg.dae"/>
      </geometry>
    </visual>
    <collision>
      <geometry>
        <mesh filename="file:///home/atas/colcon_ws/install/champ_description/share/champ_description/meshes/front_left_lower_leg_collision.stl" scale="0.82 0.97 0.98"/>
      </geometry>
    </collision>
    <collision>
      <origin xyz="0 0 -0.333"/>
      <geometry>
        <sphere radius="0.04"/>
      </geometry>
    </collision>
    <inertial>
      <origin rpy="0 0 0" xyz="0 0 -0.16"/>
      <mass value="0.5"/>
      <inertia ixx="0.007434374999999998" ixy="0.0" ixz="0.0" iyy="0.007401041666666665" iyz="0.0" izz="0.00013541666666666666"/>
    </inertial>
  </link>
  <gazebo reference="front_left_lower_leg">
    <kp>1e+07</kp>
    <kd>100.0</kd>
    <mu1>1.0</mu1>
    <mu2>1.0</mu2>
    <sensor name="contact" type="contact">
      <contact>
        <collision>front_left_lower_leg_collision</collision>
        <collision>front_left_lower_leg_collision_1</collision>
      </contact>
    </sensor>
  </gazebo>
  <joint name="front_left_knee" type="revolute">
    <origin rpy="0 0 0" xyz="0.025 0 -0.3205"/>
    <axis xyz="0 1 0"/>
    <parent link="front_left_upper_leg"/>
    <child link="front_left_lower_leg"/>
    <limit effort="160" lower="-2.7929" upper="-0.254801" velocity="30"/>
    <dynamics damping="0.0" friction="0.0"/>
  </joint>
  <link name="front_left_ee">
    <inertial>
      <origin rpy="0 0 0" xyz="0 0 0"/>
      <mass value="1e-5"/>
      <inertia ixx="1e-3" ixy="1e-6" ixz="1e-6" iyy="1e-3" iyz="1e-6" izz="1e-3"/>
    </inertial>
    <selfCollide>false</selfCollide>
  </link>
  <joint name="front_left_foot" type="fixed">
    <parent link="front_left_lower_leg"/>
    <child link="front_left_ee"/>
    <origin rpy="0 0 0" xyz="0 0 -0.37"/>
  </joint>
  <!-- workaround for https://github.com/osrf/sdformat/issues/378 -->
  <gazebo reference="front_left_foot">
    <preserveFixedJoint>true</preserveFixedJoint>
  </gazebo>
  <!-- Not actually used now, but doesn't hurt to have it here ready for future use with ros_ign_control. -->
  <transmission name="front_left_hip_x_trans">
    <type>transmission_interface/SimpleTransmission</type>
    <joint name="front_left_hip_x">
      <hardwareInterface>hardware_interface/EffortJointInterface</hardwareInterface>
    </joint>
    <actuator name="front_left_hip_x_actuator">
      <hardwareInterface>hardware_interface/EffortJointInterface</hardwareInterface>
      <mechanicalReduction>1</mechanicalReduction>
    </actuator>
  </transmission>
  <transmission name="front_left_hip_y_trans">
    <type>transmission_interface/SimpleTransmission</type>
    <joint name="front_left_hip_y">
      <hardwareInterface>hardware_interface/EffortJointInterface</hardwareInterface>
    </joint>
    <actuator name="front_left_hip_y_actuator">
      <hardwareInterface>hardware_interface/EffortJointInterface</hardwareInterface>
      <mechanicalReduction>1</mechanicalReduction>
    </actuator>
  </transmission>
  <transmission name="front_left_knee_trans">
    <type>transmission_interface/SimpleTransmission</type>
    <joint name="front_left_knee">
      <hardwareInterface>hardware_interface/EffortJointInterface</hardwareInterface>
    </joint>
    <actuator name="front_left_knee_actuator">
      <hardwareInterface>hardware_interface/EffortJointInterface</hardwareInterface>
      <mechanicalReduction>1</mechanicalReduction>
    </actuator>
  </transmission>
  <ros2_control name="GazeboSystem" type="system">
    <hardware>
      <plugin>gazebo_ros2_control/GazeboSystem</plugin>
    </hardware>
    <joint name="front_left_hip_x">
      <command_interface name="position">
        <param name="min">-3.141592653589793</param>
        <param name="max">3.141592653589793</param>
      </command_interface>
      <state_interface name="position"/>
      <state_interface name="velocity"/>
      <state_interface name="effort"/>
    </joint>
    <joint name="front_left_hip_y">
      <command_interface name="position">
        <param name="min">-3.141592653589793</param>
        <param name="max">3.141592653589793</param>
      </command_interface>
      <state_interface name="position"/>
      <state_interface name="velocity"/>
      <state_interface name="effort"/>
    </joint>
    <joint name="front_left_knee">
      <command_interface name="position">
        <param name="min">-3.141592653589793</param>
        <param name="max">3.141592653589793</param>
      </command_interface>
      <state_interface name="position"/>
      <state_interface name="velocity"/>
      <state_interface name="effort"/>
    </joint>
  </ros2_control>
  <link name="front_right_hip">
    <visual>
      <geometry>
        <mesh filename="file:///home/atas/colcon_ws/install/champ_description/share/champ_description/meshes/front_right_hip.dae"/>
      </geometry>
    </visual>
    <collision>
      <geometry>
        <mesh filename="file:///home/atas/colcon_ws/install/champ_description/share/champ_description/meshes/front_right_hip_collision.stl"/>
      </geometry>
    </collision>
    <inertial>
      <mass value="2.0"/>
      <inertia ixx="0.0026999999999999997" ixy="0.0" ixz="0.0" iyy="0.004166666666666667" iyz="0.0" izz="0.004166666666666667"/>
    </inertial>
  </link>
  <joint name="front_right_hip_x" type="revolute">
    <origin rpy="0 0 0" xyz="0.29785 -0.055 0"/>
    <axis xyz="1 0 0"/>
    <parent link="base_link"/>
    <child link="front_right_hip"/>
    <limit effort="160" lower="-0.78539816339744827899" upper="0.78539816339744827899" velocity="30"/>
    <dynamics damping="0.0" friction="0.0"/>
  </joint>
  <link name="front_right_upper_leg">
    <visual>
      <geometry>
        <mesh filename="file:///home/atas/colcon_ws/install/champ_description/share/champ_description/meshes/front_right_upper_leg.dae"/>
      </geometry>
    </visual>
    <collision>
      <geometry>
        <mesh filename="file:///home/atas/colcon_ws/install/champ_description/share/champ_description/meshes/front_right_upper_leg_collision.stl"/>
      </geometry>
    </collision>
    <inertial>
      <origin rpy="0 0 0" xyz="0 0 -0.14"/>
      <mass value="1.0"/>
      <inertia ixx="0.015533416666666664" ixy="0.0" ixz="0.0" iyy="0.015533416666666664" iyz="0.0" izz="0.0009626666666666666"/>
    </inertial>
  </link>
  <joint name="front_right_hip_y" type="revolute">
    <origin rpy="0 0 0" xyz="0 -0.110945 0"/>
    <axis xyz="0 1 0"/>
    <parent link="front_right_hip"/>
    <child link="front_right_upper_leg"/>
    <limit effort="160" lower="-0.89884456477707963539" upper="2.2951079663725435509" velocity="30"/>
    <dynamics damping="0.0" friction="0.0"/>
  </joint>
  <link name="front_right_lower_leg">
    <visual>
      <geometry>
        <mesh filename="file:///home/atas/colcon_ws/install/champ_description/share/champ_description/meshes/front_right_lower_leg.dae"/>
      </geometry>
    </visual>
    <collision>
      <geometry>
        <mesh filename="file:///home/atas/colcon_ws/install/champ_description/share/champ_description/meshes/front_right_lower_leg_collision.stl" scale="0.82 0.97 0.98"/>
      </geometry>
    </collision>
    <collision>
      <origin xyz="0 0 -0.333"/>
      <geometry>
        <sphere radius="0.04"/>
      </geometry>
    </collision>
    <inertial>
      <origin rpy="0 0 0" xyz="0 0 -0.16"/>
      <mass value="0.5"/>
      <inertia ixx="0.007434374999999998" ixy="0.0" ixz="0.0" iyy="0.007401041666666665" iyz="0.0" izz="0.00013541666666666666"/>
    </inertial>
  </link>
  <gazebo reference="front_right_lower_leg">
    <kp>1e+07</kp>
    <kd>100.0</kd>
    <mu1>1.0</mu1>
    <mu2>1.0</mu2>
    <sensor name="contact" type="contact">
      <contact>
        <collision>front_right_lower_leg_collision</collision>
        <collision>front_right_lower_leg_collision_1</collision>
      </contact>
    </sensor>
  </gazebo>
  <joint name="front_right_knee" type="revolute">
    <origin rpy="0 0 0" xyz="0.025 0 -0.3205"/>
    <axis xyz="0 1 0"/>
    <parent link="front_right_upper_leg"/>
    <child link="front_right_lower_leg"/>
    <limit effort="160" lower="-2.7929" upper="-0.254801" velocity="30"/>
    <dynamics damping="0.0" friction="0.0"/>
  </joint>
  <link name="front_right_ee">
    <inertial>
      <origin rpy="0 0 0" xyz="0 0 0"/>
      <mass value="1e-5"/>
      <inertia ixx="1e-3" ixy="1e-6" ixz="1e-6" iyy="1e-3" iyz="1e-6" izz="1e-3"/>
    </inertial>
    <selfCollide>false</selfCollide>
  </link>
  <joint name="front_right_foot" type="fixed">
    <parent link="front_right_lower_leg"/>
    <child link="front_right_ee"/>
    <origin rpy="0 0 0" xyz="0 0 -0.37"/>
  </joint>
  <!-- workaround for https://github.com/osrf/sdformat/issues/378 -->
  <gazebo reference="front_right_foot">
    <preserveFixedJoint>true</preserveFixedJoint>
  </gazebo>
  <!-- Not actually used now, but doesn't hurt to have it here ready for future use with ros_ign_control. -->
  <transmission name="front_right_hip_x_trans">
    <type>transmission_interface/SimpleTransmission</type>
    <joint name="front_right_hip_x">
      <hardwareInterface>hardware_interface/EffortJointInterface</hardwareInterface>
    </joint>
    <actuator name="front_right_hip_x_actuator">
      <hardwareInterface>hardware_interface/EffortJointInterface</hardwareInterface>
      <mechanicalReduction>1</mechanicalReduction>
    </actuator>
  </transmission>
  <transmission name="front_right_hip_y_trans">
    <type>transmission_interface/SimpleTransmission</type>
    <joint name="front_right_hip_y">
      <hardwareInterface>hardware_interface/EffortJointInterface</hardwareInterface>
    </joint>
    <actuator name="front_right_hip_y_actuator">
      <hardwareInterface>hardware_interface/EffortJointInterface</hardwareInterface>
      <mechanicalReduction>1</mechanicalReduction>
    </actuator>
  </transmission>
  <transmission name="front_right_knee_trans">
    <type>transmission_interface/SimpleTransmission</type>
    <joint name="front_right_knee">
      <hardwareInterface>hardware_interface/EffortJointInterface</hardwareInterface>
    </joint>
    <actuator name="front_right_knee_actuator">
      <hardwareInterface>hardware_interface/EffortJointInterface</hardwareInterface>
      <mechanicalReduction>1</mechanicalReduction>
    </actuator>
  </transmission>
  <ros2_control name="GazeboSystem" type="system">
    <hardware>
      <plugin>gazebo_ros2_control/GazeboSystem</plugin>
    </hardware>
    <joint name="front_right_hip_x">
      <command_interface name="position">
        <param name="min">-3.141592653589793</param>
        <param name="max">3.141592653589793</param>
      </command_interface>
      <state_interface name="position"/>
      <state_interface name="velocity"/>
      <state_interface name="effort"/>
    </joint>
    <joint name="front_right_hip_y">
      <command_interface name="position">
        <param name="min">-3.141592653589793</param>
        <param name="max">3.141592653589793</param>
      </command_interface>
      <state_interface name="position"/>
      <state_interface name="velocity"/>
      <state_interface name="effort"/>
    </joint>
    <joint name="front_right_knee">
      <command_interface name="position">
        <param name="min">-3.141592653589793</param>
        <param name="max">3.141592653589793</param>
      </command_interface>
      <state_interface name="position"/>
      <state_interface name="velocity"/>
      <state_interface name="effort"/>
    </joint>
  </ros2_control>
  <link name="rear_left_hip">
    <visual>
      <geometry>
        <mesh filename="file:///home/atas/colcon_ws/install/champ_description/share/champ_description/meshes/rear_left_hip.dae"/>
      </geometry>
    </visual>
    <collision>
      <geometry>
        <mesh filename="file:///home/atas/colcon_ws/install/champ_description/share/champ_description/meshes/rear_left_hip_collision.stl"/>
      </geometry>
    </collision>
    <inertial>
      <mass value="2.0"/>
      <inertia ixx="0.0026999999999999997" ixy="0.0" ixz="0.0" iyy="0.004166666666666667" iyz="0.0" izz="0.004166666666666667"/>
    </inertial>
  </link>
  <joint name="rear_left_hip_x" type="revolute">
    <origin rpy="0 0 0" xyz="-0.29785 0.055 0"/>
    <axis xyz="1 0 0"/>
    <parent link="base_link"/>
    <child link="rear_left_hip"/>
    <limit effort="160" lower="-0.78539816339744827899" upper="0.78539816339744827899" velocity="30"/>
    <dynamics damping="0.0" friction="0.0"/>
  </joint>
  <link name="rear_left_upper_leg">
    <visual>
      <geometry>
        <mesh filename="file:///home/atas/colcon_ws/install/champ_description/share/champ_description/meshes/rear_left_upper_leg.dae"/>
      </geometry>
    </visual>
    <collision>
      <geometry>
        <mesh filename="file:///home/atas/colcon_ws/install/champ_description/share/champ_description/meshes/rear_left_upper_leg_collision.stl"/>
      </geometry>
    </collision>
    <inertial>
      <origin rpy="0 0 0" xyz="0 0 -0.14"/>
      <mass value="1.0"/>
      <inertia ixx="0.015533416666666664" ixy="0.0" ixz="0.0" iyy="0.015533416666666664" iyz="0.0" izz="0.0009626666666666666"/>
    </inertial>
  </link>
  <joint name="rear_left_hip_y" type="revolute">
    <origin rpy="0 0 0" xyz="0 0.110945 0"/>
    <axis xyz="0 1 0"/>
    <parent link="rear_left_hip"/>
    <child link="rear_left_upper_leg"/>
    <limit effort="160" lower="-0.89884456477707963539" upper="2.2951079663725435509" velocity="30"/>
    <dynamics damping="0.0" friction="0.0"/>
  </joint>
  <link name="rear_left_lower_leg">
    <visual>
      <geometry>
        <mesh filename="file:///home/atas/colcon_ws/install/champ_description/share/champ_description/meshes/rear_left_lower_leg.dae"/>
      </geometry>
    </visual>
    <collision>
      <geometry>
        <mesh filename="file:///home/atas/colcon_ws/install/champ_description/share/champ_description/meshes/rear_left_lower_leg_collision.stl" scale="0.82 0.97 0.98"/>
      </geometry>
    </collision>
    <collision>
      <origin xyz="0 0 -0.333"/>
      <geometry>
        <sphere radius="0.04"/>
      </geometry>
    </collision>
    <inertial>
      <origin rpy="0 0 0" xyz="0 0 -0.16"/>
      <mass value="0.5"/>
      <inertia ixx="0.007434374999999998" ixy="0.0" ixz="0.0" iyy="0.007401041666666665" iyz="0.0" izz="0.00013541666666666666"/>
    </inertial>
  </link>
  <gazebo reference="rear_left_lower_leg">
    <kp>1e+07</kp>
    <kd>100.0</kd>
    <mu1>1.0</mu1>
    <mu2>1.0</mu2>
    <sensor name="contact" type="contact">
      <contact>
        <collision>rear_left_lower_leg_collision</collision>
        <collision>rear_left_lower_leg_collision_1</collision>
      </contact>
    </sensor>
  </gazebo>
  <joint name="rear_left_knee" type="revolute">
    <origin rpy="0 0 0" xyz="0.025 0 -0.3205"/>
    <axis xyz="0 1 0"/>
    <parent link="rear_left_upper_leg"/>
    <child link="rear_left_lower_leg"/>
    <limit effort="160" lower="-2.7929" upper="-0.254801" velocity="30"/>
    <dynamics damping="0.0" friction="0.0"/>
  </joint>
  <link name="rear_left_ee">
    <inertial>
      <origin rpy="0 0 0" xyz="0 0 0"/>
      <mass value="1e-5"/>
      <inertia ixx="1e-3" ixy="1e-6" ixz="1e-6" iyy="1e-3" iyz="1e-6" izz="1e-3"/>
    </inertial>
    <selfCollide>false</selfCollide>
  </link>
  <joint name="rear_left_foot" type="fixed">
    <parent link="rear_left_lower_leg"/>
    <child link="rear_left_ee"/>
    <origin rpy="0 0 0" xyz="0 0 -0.37"/>
  </joint>
  <!-- workaround for https://github.com/osrf/sdformat/issues/378 -->
  <gazebo reference="rear_left_foot">
    <preserveFixedJoint>true</preserveFixedJoint>
  </gazebo>
  <!-- Not actually used now, but doesn't hurt to have it here ready for future use with ros_ign_control. -->
  <transmission name="rear_left_hip_x_trans">
    <type>transmission_interface/SimpleTransmission</type>
    <joint name="rear_left_hip_x">
      <hardwareInterface>hardware_interface/EffortJointInterface</hardwareInterface>
    </joint>
    <actuator name="rear_left_hip_x_actuator">
      <hardwareInterface>hardware_interface/EffortJointInterface</hardwareInterface>
      <mechanicalReduction>1</mechanicalReduction>
    </actuator>
  </transmission>
  <transmission name="rear_left_hip_y_trans">
    <type>transmission_interface/SimpleTransmission</type>
    <joint name="rear_left_hip_y">
      <hardwareInterface>hardware_interface/EffortJointInterface</hardwareInterface>
    </joint>
    <actuator name="rear_left_hip_y_actuator">
      <hardwareInterface>hardware_interface/EffortJointInterface</hardwareInterface>
      <mechanicalReduction>1</mechanicalReduction>
    </actuator>
  </transmission>
  <transmission name="rear_left_knee_trans">
    <type>transmission_interface/SimpleTransmission</type>
    <joint name="rear_left_knee">
      <hardwareInterface>hardware_interface/EffortJointInterface</hardwareInterface>
    </joint>
    <actuator name="rear_left_knee_actuator">
      <hardwareInterface>hardware_interface/EffortJointInterface</hardwareInterface>
      <mechanicalReduction>1</mechanicalReduction>
    </actuator>
  </transmission>
  <ros2_control name="GazeboSystem" type="system">
    <hardware>
      <plugin>gazebo_ros2_control/GazeboSystem</plugin>
    </hardware>
    <joint name="rear_left_hip_x">
      <command_interface name="position">
        <param name="min">-3.141592653589793</param>
        <param name="max">3.141592653589793</param>
      </command_interface>
      <state_interface name="position"/>
      <state_interface name="velocity"/>
      <state_interface name="effort"/>
    </joint>
    <joint name="rear_left_hip_y">
      <command_interface name="position">
        <param name="min">-3.141592653589793</param>
        <param name="max">3.141592653589793</param>
      </command_interface>
      <state_interface name="position"/>
      <state_interface name="velocity"/>
      <state_interface name="effort"/>
    </joint>
    <joint name="rear_left_knee">
      <command_interface name="position">
        <param name="min">-3.141592653589793</param>
        <param name="max">3.141592653589793</param>
      </command_interface>
      <state_interface name="position"/>
      <state_interface name="velocity"/>
      <state_interface name="effort"/>
    </joint>
  </ros2_control>
  <link name="rear_right_hip">
    <visual>
      <geometry>
        <mesh filename="file:///home/atas/colcon_ws/install/champ_description/share/champ_description/meshes/rear_right_hip.dae"/>
      </geometry>
    </visual>
    <collision>
      <geometry>
        <mesh filename="file:///home/atas/colcon_ws/install/champ_description/share/champ_description/meshes/rear_right_hip_collision.stl"/>
      </geometry>
    </collision>
    <inertial>
      <mass value="2.0"/>
      <inertia ixx="0.0026999999999999997" ixy="0.0" ixz="0.0" iyy="0.004166666666666667" iyz="0.0" izz="0.004166666666666667"/>
    </inertial>
  </link>
  <joint name="rear_right_hip_x" type="revolute">
    <origin rpy="0 0 0" xyz="-0.29785 -0.055 0"/>
    <axis xyz="1 0 0"/>
    <parent link="base_link"/>
    <child link="rear_right_hip"/>
    <limit effort="160" lower="-0.78539816339744827899" upper="0.78539816339744827899" velocity="30"/>
    <dynamics damping="0.0" friction="0.0"/>
  </joint>
  <link name="rear_right_upper_leg">
    <visual>
      <geometry>
        <mesh filename="file:///home/atas/colcon_ws/install/champ_description/share/champ_description/meshes/rear_right_upper_leg.dae"/>
      </geometry>
    </visual>
    <collision>
      <geometry>
        <mesh filename="file:///home/atas/colcon_ws/install/champ_description/share/champ_description/meshes/rear_right_upper_leg_collision.stl"/>
      </geometry>
    </collision>
    <inertial>
      <origin rpy="0 0 0" xyz="0 0 -0.14"/>
      <mass value="1.0"/>
      <inertia ixx="0.015533416666666664" ixy="0.0" ixz="0.0" iyy="0.015533416666666664" iyz="0.0" izz="0.0009626666666666666"/>
    </inertial>
  </link>
  <joint name="rear_right_hip_y" type="revolute">
    <origin rpy="0 0 0" xyz="0 -0.110945 0"/>
    <axis xyz="0 1 0"/>
    <parent link="rear_right_hip"/>
    <child link="rear_right_upper_leg"/>
    <limit effort="160" lower="-0.89884456477707963539" upper="2.2951079663725435509" velocity="30"/>
    <dynamics damping="0.0" friction="0.0"/>
  </joint>
  <link name="rear_right_lower_leg">
    <visual>
      <geometry>
        <mesh filename="file:///home/atas/colcon_ws/install/champ_description/share/champ_description/meshes/rear_right_lower_leg.dae"/>
      </geometry>
    </visual>
    <collision>
      <geometry>
        <mesh filename="file:///home/atas/colcon_ws/install/champ_description/share/champ_description/meshes/rear_right_lower_leg_collision.stl" scale="0.82 0.97 0.98"/>
      </geometry>
    </collision>
    <collision>
      <origin xyz="0 0 -0.333"/>
      <geometry>
        <sphere radius="0.04"/>
      </geometry>
    </collision>
    <inertial>
      <origin rpy="0 0 0" xyz="0 0 -0.16"/>
      <mass value="0.5"/>
      <inertia ixx="0.007434374999999998" ixy="0.0" ixz="0.0" iyy="0.007401041666666665" iyz="0.0" izz="0.00013541666666666666"/>
    </inertial>
  </link>
  <gazebo reference="rear_right_lower_leg">
    <kp>1e+07</kp>
    <kd>100.0</kd>
    <mu1>1.0</mu1>
    <mu2>1.0</mu2>
    <sensor name="contact" type="contact">
      <contact>
        <collision>rear_right_lower_leg_collision</collision>
        <collision>rear_right_lower_leg_collision_1</collision>
      </contact>
    </sensor>
  </gazebo>
  <joint name="rear_right_knee" type="revolute">
    <origin rpy="0 0 0" xyz="0.025 0 -0.3205"/>
    <axis xyz="0 1 0"/>
    <parent link="rear_right_upper_leg"/>
    <child link="rear_right_lower_leg"/>
    <limit effort="160" lower="-2.7929" upper="-0.254801" velocity="30"/>
    <dynamics damping="0.0" friction="0.0"/>
  </joint>
  <link name="rear_right_ee">
    <inertial>
      <origin rpy="0 0 0" xyz="0 0 0"/>
      <mass value="1e-5"/>
      <inertia ixx="1e-3" ixy="1e-6" ixz="1e-6" iyy="1e-3" iyz="1e-6" izz="1e-3"/>
    </inertial>
    <selfCollide>false</selfCollide>
  </link>
  <joint name="rear_right_foot" type="fixed">
    <parent link="rear_right_lower_leg"/>
    <child link="rear_right_ee"/>
    <origin rpy="0 0 0" xyz="0 0 -0.37"/>
  </joint>
  <!-- workaround for https://github.com/osrf/sdformat/issues/378 -->
  <gazebo reference="rear_right_foot">
    <preserveFixedJoint>true</preserveFixedJoint>
  </gazebo>
  <!-- Not actually used now, but doesn't hurt to have it here ready for future use with ros_ign_control. -->
  <transmission name="rear_right_hip_x_trans">
    <type>transmission_interface/SimpleTransmission</type>
    <joint name="rear_right_hip_x">
      <hardwareInterface>hardware_interface/EffortJointInterface</hardwareInterface>
    </joint>
    <actuator name="rear_right_hip_x_actuator">
      <hardwareInterface>hardware_interface/EffortJointInterface</hardwareInterface>
      <mechanicalReduction>1</mechanicalReduction>
    </actuator>
  </transmission>
  <transmission name="rear_right_hip_y_trans">
    <type>transmission_interface/SimpleTransmission</type>
    <joint name="rear_right_hip_y">
      <hardwareInterface>hardware_interface/EffortJointInterface</hardwareInterface>
    </joint>
    <actuator name="rear_right_hip_y_actuator">
      <hardwareInterface>hardware_interface/EffortJointInterface</hardwareInterface>
      <mechanicalReduction>1</mechanicalReduction>
    </actuator>
  </transmission>
  <transmission name="rear_right_knee_trans">
    <type>transmission_interface/SimpleTransmission</type>
    <joint name="rear_right_knee">
      <hardwareInterface>hardware_interface/EffortJointInterface</hardwareInterface>
    </joint>
    <actuator name="rear_right_knee_actuator">
      <hardwareInterface>hardware_interface/EffortJointInterface</hardwareInterface>
      <mechanicalReduction>1</mechanicalReduction>
    </actuator>
  </transmission>
  <ros2_control name="GazeboSystem" type="system">
    <hardware>
      <plugin>gazebo_ros2_control/GazeboSystem</plugin>
    </hardware>
    <joint name="rear_right_hip_x">
      <command_interface name="position">
        <param name="min">-3.141592653589793</param>
        <param name="max">3.141592653589793</param>
      </command_interface>
      <state_interface name="position"/>
      <state_interface name="velocity"/>
      <state_interface name="effort"/>
    </joint>
    <joint name="rear_right_hip_y">
      <command_interface name="position">
        <param name="min">-3.141592653589793</param>
        <param name="max">3.141592653589793</param>
      </command_interface>
      <state_interface name="position"/>
      <state_interface name="velocity"/>
      <state_interface name="effort"/>
    </joint>
    <joint name="rear_right_knee">
      <command_interface name="position">
        <param name="min">-3.141592653589793</param>
        <param name="max">3.141592653589793</param>
      </command_interface>
      <state_interface name="position"/>
      <state_interface name="velocity"/>
      <state_interface name="effort"/>
    </joint>
  </ros2_control>
  <link name="imu">
    <inertial>
      <origin rpy="0 0 0" xyz="0 0 0"/>
      <mass value="1e-5"/>
      <inertia ixx="1e-3" ixy="1e-6" ixz="1e-6" iyy="1e-3" iyz="1e-6" izz="1e-3"/>
    </inertial>
    <selfCollide>false</selfCollide>
  </link>
  <joint name="imu_j" type="fixed">
    <parent link="base_link"/>
    <child link="imu"/>
    <origin rpy="0 0 0" xyz="0 0 0"/>
  </joint>
  <!-- workaround for https://github.com/osrf/sdformat/issues/378 -->
  <gazebo reference="imu_j">
    <preserveFixedJoint>true</preserveFixedJoint>
  </gazebo>
  <gazebo reference="imu">
  </gazebo>
  <!-- Body cameras -->
  <link name="camera_frontleft">
    <inertial>
      <origin rpy="0 0 0" xyz="0 0 0"/>
      <mass value="1e-5"/>
      <inertia ixx="1e-3" ixy="1e-6" ixz="1e-6" iyy="1e-3" iyz="1e-6" izz="1e-3"/>
    </inertial>
  </link>
  <joint name="camera_frontleft_j" type="fixed">
    <parent link="base_link"/>
    <child link="camera_frontleft"/>
    <origin rpy="1.355558 0.353917 -0.554196" xyz="0.415 0.037 -0.01"/>
  </joint>
  <!-- workaround for https://github.com/osrf/sdformat/issues/378 -->
  <gazebo reference="camera_frontleft_j">
    <preserveFixedJoint>true</preserveFixedJoint>
  </gazebo>
  <link name="camera_frontright">
    <inertial>
      <origin rpy="0 0 0" xyz="0 0 0"/>
      <mass value="1e-5"/>
      <inertia ixx="1e-3" ixy="1e-6" ixz="1e-6" iyy="1e-3" iyz="1e-6" izz="1e-3"/>
    </inertial>
  </link>
  <joint name="camera_frontright_j" type="fixed">
    <parent link="base_link"/>
    <child link="camera_frontright"/>
    <origin rpy="-1.355558 0.353917 0.554196" xyz="0.415 -0.037 -0.01"/>
  </joint>
  <!-- workaround for https://github.com/osrf/sdformat/issues/378 -->
  <gazebo reference="camera_frontright_j">
    <preserveFixedJoint>true</preserveFixedJoint>
  </gazebo>
  <link name="camera_left">
    <inertial>
      <origin rpy="0 0 0" xyz="0 0 0"/>
      <mass value="1e-5"/>
      <inertia ixx="1e-3" ixy="1e-6" ixz="1e-6" iyy="1e-3" iyz="1e-6" izz="1e-3"/>
    </inertial>
  </link>
  <joint name="camera_left_j" type="fixed">
    <parent link="base_link"/>
    <child link="camera_left"/>
    <origin rpy="0 0.2 1.5707963267948966" xyz="-0.125 0.12 0.035"/>
  </joint>
  <!-- workaround for https://github.com/osrf/sdformat/issues/378 -->
  <gazebo reference="camera_left_j">
    <preserveFixedJoint>true</preserveFixedJoint>
  </gazebo>
  <link name="camera_right">
    <inertial>
      <origin rpy="0 0 0" xyz="0 0 0"/>
      <mass value="1e-5"/>
      <inertia ixx="1e-3" ixy="1e-6" ixz="1e-6" iyy="1e-3" iyz="1e-6" izz="1e-3"/>
    </inertial>
  </link>
  <joint name="camera_right_j" type="fixed">
    <parent link="base_link"/>
    <child link="camera_right"/>
    <origin rpy="0 0.2 -1.5707963267948966" xyz="-0.125 -0.12 0.035"/>
  </joint>
  <!-- workaround for https://github.com/osrf/sdformat/issues/378 -->
  <gazebo reference="camera_right_j">
    <preserveFixedJoint>true</preserveFixedJoint>
  </gazebo>
  <link name="camera_back">
    <inertial>
      <origin rpy="0 0 0" xyz="0 0 0"/>
      <mass value="1e-5"/>
      <inertia ixx="1e-3" ixy="1e-6" ixz="1e-6" iyy="1e-3" iyz="1e-6" izz="1e-3"/>
    </inertial>
  </link>
  <joint name="camera_back_j" type="fixed">
    <parent link="base_link"/>
    <child link="camera_back"/>
    <origin rpy="0 0.3 -3.141592653589793" xyz="-0.425 0 0.01"/>
  </joint>
  <!-- workaround for https://github.com/osrf/sdformat/issues/378 -->
  <gazebo reference="camera_back_j">
    <preserveFixedJoint>true</preserveFixedJoint>
  </gazebo>
  <gazebo>
    <plugin filename="libgazebo_ros_p3d.so" name="p3d_base_controller">
      <ros>
        <namespace/>
        <remapping>odom:=odom/ground_truth</remapping>
      </ros>
      <body_name>base_link</body_name>
      <update_rate>20</update_rate>
      <xyz_offset>0 0 0</xyz_offset>
      <rpy_offset>0.0 0.0 0.0</rpy_offset>
      <gaussian_noise>0.01</gaussian_noise>
    </plugin>
  </gazebo>
  <gazebo>
    <plugin filename="libgazebo_ros2_control.so" name="gazebo_ros2_control">
      <parameters>/home/atas/colcon_ws/install/champ_bringup/share/champ_bringup/config/ros2_control_spot.yaml</parameters>
    </plugin>
  </gazebo>
</robot>
